2018-12-23 21:13:38,691 INFO: Microblog startup [in ./app/__init__.py:49]
2018-12-23 21:13:39,277 INFO: Microblog startup [in ./app/__init__.py:49]
2019-01-02 14:14:33,016 INFO: Microblog startup [in C:\Users\supratimdas\PycharmProjects\Flask_Tutorials\app\__init__.py:49]
2019-01-02 14:14:41,467 INFO: Microblog startup [in C:\Users\supratimdas\PycharmProjects\Flask_Tutorials\app\__init__.py:49]
2019-01-02 14:14:47,849 INFO: Microblog startup [in C:\Users\supratimdas\PycharmProjects\Flask_Tutorials\app\__init__.py:49]
2019-01-02 14:14:52,950 ERROR: Exception on /favicon.ico [GET] [in c:\users\supratimdas\pycharmprojects\preprocessingpipelinempfe\flask_tutorials\lib\site-packages\flask\app.py:1761]
Traceback (most recent call last):
  File "c:\users\supratimdas\pycharmprojects\preprocessingpipelinempfe\flask_tutorials\lib\site-packages\flask\app.py", line 2292, in wsgi_app
    response = self.full_dispatch_request()
  File "c:\users\supratimdas\pycharmprojects\preprocessingpipelinempfe\flask_tutorials\lib\site-packages\flask\app.py", line 1815, in full_dispatch_request
    rv = self.handle_user_exception(e)
  File "c:\users\supratimdas\pycharmprojects\preprocessingpipelinempfe\flask_tutorials\lib\site-packages\flask\app.py", line 1713, in handle_user_exception
    return self.handle_http_exception(e)
  File "c:\users\supratimdas\pycharmprojects\preprocessingpipelinempfe\flask_tutorials\lib\site-packages\flask\app.py", line 1644, in handle_http_exception
    return handler(e)
TypeError: not_found_error() takes no arguments (1 given)
2019-01-02 14:15:07,733 ERROR: Exception on /favicon.ico [GET] [in c:\users\supratimdas\pycharmprojects\preprocessingpipelinempfe\flask_tutorials\lib\site-packages\flask\app.py:1761]
Traceback (most recent call last):
  File "c:\users\supratimdas\pycharmprojects\preprocessingpipelinempfe\flask_tutorials\lib\site-packages\flask\app.py", line 2292, in wsgi_app
    response = self.full_dispatch_request()
  File "c:\users\supratimdas\pycharmprojects\preprocessingpipelinempfe\flask_tutorials\lib\site-packages\flask\app.py", line 1815, in full_dispatch_request
    rv = self.handle_user_exception(e)
  File "c:\users\supratimdas\pycharmprojects\preprocessingpipelinempfe\flask_tutorials\lib\site-packages\flask\app.py", line 1713, in handle_user_exception
    return self.handle_http_exception(e)
  File "c:\users\supratimdas\pycharmprojects\preprocessingpipelinempfe\flask_tutorials\lib\site-packages\flask\app.py", line 1644, in handle_http_exception
    return handler(e)
TypeError: not_found_error() takes no arguments (1 given)
2019-01-02 14:24:44,213 INFO: Microblog startup [in C:\Users\supratimdas\PycharmProjects\Flask_Tutorials\app\__init__.py:49]
2019-01-02 14:24:53,928 INFO: Microblog startup [in C:\Users\supratimdas\PycharmProjects\Flask_Tutorials\app\__init__.py:49]
2019-01-02 14:52:03,424 INFO: Microblog startup [in C:\Users\supratimdas\PycharmProjects\Flask_Tutorials\app\__init__.py:51]
2019-01-02 14:52:14,676 ERROR: Exception on /favicon.ico [GET] [in c:\users\supratimdas\pycharmprojects\preprocessingpipelinempfe\flask_tutorials\lib\site-packages\flask\app.py:1761]
Traceback (most recent call last):
  File "c:\users\supratimdas\pycharmprojects\preprocessingpipelinempfe\flask_tutorials\lib\site-packages\flask\app.py", line 2292, in wsgi_app
    response = self.full_dispatch_request()
  File "c:\users\supratimdas\pycharmprojects\preprocessingpipelinempfe\flask_tutorials\lib\site-packages\flask\app.py", line 1815, in full_dispatch_request
    rv = self.handle_user_exception(e)
  File "c:\users\supratimdas\pycharmprojects\preprocessingpipelinempfe\flask_tutorials\lib\site-packages\flask\app.py", line 1713, in handle_user_exception
    return self.handle_http_exception(e)
  File "c:\users\supratimdas\pycharmprojects\preprocessingpipelinempfe\flask_tutorials\lib\site-packages\flask\app.py", line 1644, in handle_http_exception
    return handler(e)
TypeError: not_found_error() takes no arguments (1 given)
2019-01-02 14:52:25,236 ERROR: Exception on /favicon.ico [GET] [in c:\users\supratimdas\pycharmprojects\preprocessingpipelinempfe\flask_tutorials\lib\site-packages\flask\app.py:1761]
Traceback (most recent call last):
  File "c:\users\supratimdas\pycharmprojects\preprocessingpipelinempfe\flask_tutorials\lib\site-packages\flask\app.py", line 2292, in wsgi_app
    response = self.full_dispatch_request()
  File "c:\users\supratimdas\pycharmprojects\preprocessingpipelinempfe\flask_tutorials\lib\site-packages\flask\app.py", line 1815, in full_dispatch_request
    rv = self.handle_user_exception(e)
  File "c:\users\supratimdas\pycharmprojects\preprocessingpipelinempfe\flask_tutorials\lib\site-packages\flask\app.py", line 1713, in handle_user_exception
    return self.handle_http_exception(e)
  File "c:\users\supratimdas\pycharmprojects\preprocessingpipelinempfe\flask_tutorials\lib\site-packages\flask\app.py", line 1644, in handle_http_exception
    return handler(e)
TypeError: not_found_error() takes no arguments (1 given)
2019-01-02 14:52:25,371 ERROR: Exception on /favicon.ico [GET] [in c:\users\supratimdas\pycharmprojects\preprocessingpipelinempfe\flask_tutorials\lib\site-packages\flask\app.py:1761]
Traceback (most recent call last):
  File "c:\users\supratimdas\pycharmprojects\preprocessingpipelinempfe\flask_tutorials\lib\site-packages\flask\app.py", line 2292, in wsgi_app
    response = self.full_dispatch_request()
  File "c:\users\supratimdas\pycharmprojects\preprocessingpipelinempfe\flask_tutorials\lib\site-packages\flask\app.py", line 1815, in full_dispatch_request
    rv = self.handle_user_exception(e)
  File "c:\users\supratimdas\pycharmprojects\preprocessingpipelinempfe\flask_tutorials\lib\site-packages\flask\app.py", line 1713, in handle_user_exception
    return self.handle_http_exception(e)
  File "c:\users\supratimdas\pycharmprojects\preprocessingpipelinempfe\flask_tutorials\lib\site-packages\flask\app.py", line 1644, in handle_http_exception
    return handler(e)
TypeError: not_found_error() takes no arguments (1 given)
2019-01-02 14:59:00,214 INFO: Microblog startup [in C:\Users\supratimdas\PycharmProjects\Flask_Tutorials\app\__init__.py:51]
2019-01-02 14:59:05,749 ERROR: Exception on /favicon.ico [GET] [in c:\users\supratimdas\pycharmprojects\preprocessingpipelinempfe\flask_tutorials\lib\site-packages\flask\app.py:1761]
Traceback (most recent call last):
  File "c:\users\supratimdas\pycharmprojects\preprocessingpipelinempfe\flask_tutorials\lib\site-packages\flask\app.py", line 2292, in wsgi_app
    response = self.full_dispatch_request()
  File "c:\users\supratimdas\pycharmprojects\preprocessingpipelinempfe\flask_tutorials\lib\site-packages\flask\app.py", line 1815, in full_dispatch_request
    rv = self.handle_user_exception(e)
  File "c:\users\supratimdas\pycharmprojects\preprocessingpipelinempfe\flask_tutorials\lib\site-packages\flask\app.py", line 1713, in handle_user_exception
    return self.handle_http_exception(e)
  File "c:\users\supratimdas\pycharmprojects\preprocessingpipelinempfe\flask_tutorials\lib\site-packages\flask\app.py", line 1644, in handle_http_exception
    return handler(e)
TypeError: not_found_error() takes no arguments (1 given)
2019-01-02 15:01:30,105 INFO: Microblog startup [in C:\Users\supratimdas\PycharmProjects\Flask_Tutorials\app\__init__.py:51]
2019-01-02 15:01:36,240 ERROR: Exception on /favicon.ico [GET] [in c:\users\supratimdas\pycharmprojects\preprocessingpipelinempfe\flask_tutorials\lib\site-packages\flask\app.py:1761]
Traceback (most recent call last):
  File "c:\users\supratimdas\pycharmprojects\preprocessingpipelinempfe\flask_tutorials\lib\site-packages\flask\app.py", line 2292, in wsgi_app
    response = self.full_dispatch_request()
  File "c:\users\supratimdas\pycharmprojects\preprocessingpipelinempfe\flask_tutorials\lib\site-packages\flask\app.py", line 1815, in full_dispatch_request
    rv = self.handle_user_exception(e)
  File "c:\users\supratimdas\pycharmprojects\preprocessingpipelinempfe\flask_tutorials\lib\site-packages\flask\app.py", line 1713, in handle_user_exception
    return self.handle_http_exception(e)
  File "c:\users\supratimdas\pycharmprojects\preprocessingpipelinempfe\flask_tutorials\lib\site-packages\flask\app.py", line 1644, in handle_http_exception
    return handler(e)
TypeError: not_found_error() takes no arguments (1 given)
2019-01-02 15:03:37,743 INFO: Microblog startup [in C:\Users\supratimdas\PycharmProjects\Flask_Tutorials\app\__init__.py:51]
2019-01-02 15:03:40,910 ERROR: Exception on /favicon.ico [GET] [in c:\users\supratimdas\pycharmprojects\preprocessingpipelinempfe\flask_tutorials\lib\site-packages\flask\app.py:1761]
Traceback (most recent call last):
  File "c:\users\supratimdas\pycharmprojects\preprocessingpipelinempfe\flask_tutorials\lib\site-packages\flask\app.py", line 2292, in wsgi_app
    response = self.full_dispatch_request()
  File "c:\users\supratimdas\pycharmprojects\preprocessingpipelinempfe\flask_tutorials\lib\site-packages\flask\app.py", line 1815, in full_dispatch_request
    rv = self.handle_user_exception(e)
  File "c:\users\supratimdas\pycharmprojects\preprocessingpipelinempfe\flask_tutorials\lib\site-packages\flask\app.py", line 1713, in handle_user_exception
    return self.handle_http_exception(e)
  File "c:\users\supratimdas\pycharmprojects\preprocessingpipelinempfe\flask_tutorials\lib\site-packages\flask\app.py", line 1644, in handle_http_exception
    return handler(e)
TypeError: not_found_error() takes no arguments (1 given)
2019-01-02 15:04:29,759 INFO: Microblog startup [in C:\Users\supratimdas\PycharmProjects\Flask_Tutorials\app\__init__.py:51]
