2018-12-23 17:01:00,762 ERROR: Exception on / [GET] [in /Users/Supra/PycharmProjects/Flask_Tutorials/venv/lib/python2.7/site-packages/flask/app.py:1761]
Traceback (most recent call last):
  File "/Users/Supra/PycharmProjects/Flask_Tutorials/venv/lib/python2.7/site-packages/flask/app.py", line 2292, in wsgi_app
    response = self.full_dispatch_request()
  File "/Users/Supra/PycharmProjects/Flask_Tutorials/venv/lib/python2.7/site-packages/flask/app.py", line 1815, in full_dispatch_request
    rv = self.handle_user_exception(e)
  File "/Users/Supra/PycharmProjects/Flask_Tutorials/venv/lib/python2.7/site-packages/flask/app.py", line 1718, in handle_user_exception
    reraise(exc_type, exc_value, tb)
  File "/Users/Supra/PycharmProjects/Flask_Tutorials/venv/lib/python2.7/site-packages/flask/app.py", line 1813, in full_dispatch_request
    rv = self.dispatch_request()
  File "/Users/Supra/PycharmProjects/Flask_Tutorials/venv/lib/python2.7/site-packages/flask/app.py", line 1799, in dispatch_request
    return self.view_functions[rule.endpoint](**req.view_args)
  File "/Users/Supra/PycharmProjects/Flask_Tutorials/venv/lib/python2.7/site-packages/flask_login/utils.py", line 261, in decorated_view
    return func(*args, **kwargs)
  File "/Users/Supra/PycharmProjects/Flask_Tutorials/app/routes.py", line 35, in index
    prev_url=prev_url)
  File "/Users/Supra/PycharmProjects/Flask_Tutorials/venv/lib/python2.7/site-packages/flask/templating.py", line 135, in render_template
    context, ctx.app)
  File "/Users/Supra/PycharmProjects/Flask_Tutorials/venv/lib/python2.7/site-packages/flask/templating.py", line 117, in _render
    rv = template.render(context)
  File "/Users/Supra/PycharmProjects/Flask_Tutorials/venv/lib/python2.7/site-packages/jinja2/environment.py", line 1008, in render
    return self.environment.handle_exception(exc_info, True)
  File "/Users/Supra/PycharmProjects/Flask_Tutorials/venv/lib/python2.7/site-packages/jinja2/environment.py", line 780, in handle_exception
    reraise(exc_type, exc_value, tb)
  File "/Users/Supra/PycharmProjects/Flask_Tutorials/app/templates/base.html", line 71, in template
    {% block content %}
TemplateAssertionError: block 'content' defined twice
2018-12-23 17:01:01,638 ERROR: Exception on /favicon.ico [GET] [in /Users/Supra/PycharmProjects/Flask_Tutorials/venv/lib/python2.7/site-packages/flask/app.py:1761]
Traceback (most recent call last):
  File "/Users/Supra/PycharmProjects/Flask_Tutorials/venv/lib/python2.7/site-packages/flask/app.py", line 2292, in wsgi_app
    response = self.full_dispatch_request()
  File "/Users/Supra/PycharmProjects/Flask_Tutorials/venv/lib/python2.7/site-packages/flask/app.py", line 1815, in full_dispatch_request
    rv = self.handle_user_exception(e)
  File "/Users/Supra/PycharmProjects/Flask_Tutorials/venv/lib/python2.7/site-packages/flask/app.py", line 1713, in handle_user_exception
    return self.handle_http_exception(e)
  File "/Users/Supra/PycharmProjects/Flask_Tutorials/venv/lib/python2.7/site-packages/flask/app.py", line 1644, in handle_http_exception
    return handler(e)
TypeError: not_found_error() takes no arguments (1 given)
2018-12-23 17:01:27,027 INFO: Microblog startup [in /Users/Supra/PycharmProjects/Flask_Tutorials/app/__init__.py:49]
2018-12-23 17:01:28,476 ERROR: Exception on / [GET] [in /Users/Supra/PycharmProjects/Flask_Tutorials/venv/lib/python2.7/site-packages/flask/app.py:1761]
Traceback (most recent call last):
  File "/Users/Supra/PycharmProjects/Flask_Tutorials/venv/lib/python2.7/site-packages/flask/app.py", line 2292, in wsgi_app
    response = self.full_dispatch_request()
  File "/Users/Supra/PycharmProjects/Flask_Tutorials/venv/lib/python2.7/site-packages/flask/app.py", line 1815, in full_dispatch_request
    rv = self.handle_user_exception(e)
  File "/Users/Supra/PycharmProjects/Flask_Tutorials/venv/lib/python2.7/site-packages/flask/app.py", line 1718, in handle_user_exception
    reraise(exc_type, exc_value, tb)
  File "/Users/Supra/PycharmProjects/Flask_Tutorials/venv/lib/python2.7/site-packages/flask/app.py", line 1813, in full_dispatch_request
    rv = self.dispatch_request()
  File "/Users/Supra/PycharmProjects/Flask_Tutorials/venv/lib/python2.7/site-packages/flask/app.py", line 1799, in dispatch_request
    return self.view_functions[rule.endpoint](**req.view_args)
  File "/Users/Supra/PycharmProjects/Flask_Tutorials/venv/lib/python2.7/site-packages/flask_login/utils.py", line 261, in decorated_view
    return func(*args, **kwargs)
  File "/Users/Supra/PycharmProjects/Flask_Tutorials/app/routes.py", line 35, in index
    prev_url=prev_url)
  File "/Users/Supra/PycharmProjects/Flask_Tutorials/venv/lib/python2.7/site-packages/flask/templating.py", line 135, in render_template
    context, ctx.app)
  File "/Users/Supra/PycharmProjects/Flask_Tutorials/venv/lib/python2.7/site-packages/flask/templating.py", line 117, in _render
    rv = template.render(context)
  File "/Users/Supra/PycharmProjects/Flask_Tutorials/venv/lib/python2.7/site-packages/jinja2/environment.py", line 1008, in render
    return self.environment.handle_exception(exc_info, True)
  File "/Users/Supra/PycharmProjects/Flask_Tutorials/venv/lib/python2.7/site-packages/jinja2/environment.py", line 780, in handle_exception
    reraise(exc_type, exc_value, tb)
  File "/Users/Supra/PycharmProjects/Flask_Tutorials/app/templates/index.html", line 2, in top-level template code
    <!--{% extends "base.html" %}-->
TemplateRuntimeError: extended multiple times
2018-12-23 17:01:29,423 ERROR: Exception on /favicon.ico [GET] [in /Users/Supra/PycharmProjects/Flask_Tutorials/venv/lib/python2.7/site-packages/flask/app.py:1761]
Traceback (most recent call last):
  File "/Users/Supra/PycharmProjects/Flask_Tutorials/venv/lib/python2.7/site-packages/flask/app.py", line 2292, in wsgi_app
    response = self.full_dispatch_request()
  File "/Users/Supra/PycharmProjects/Flask_Tutorials/venv/lib/python2.7/site-packages/flask/app.py", line 1815, in full_dispatch_request
    rv = self.handle_user_exception(e)
  File "/Users/Supra/PycharmProjects/Flask_Tutorials/venv/lib/python2.7/site-packages/flask/app.py", line 1713, in handle_user_exception
    return self.handle_http_exception(e)
  File "/Users/Supra/PycharmProjects/Flask_Tutorials/venv/lib/python2.7/site-packages/flask/app.py", line 1644, in handle_http_exception
    return handler(e)
TypeError: not_found_error() takes no arguments (1 given)
2018-12-23 17:02:50,170 INFO: Microblog startup [in /Users/Supra/PycharmProjects/Flask_Tutorials/app/__init__.py:49]
2018-12-23 17:02:52,614 ERROR: Exception on /favicon.ico [GET] [in /Users/Supra/PycharmProjects/Flask_Tutorials/venv/lib/python2.7/site-packages/flask/app.py:1761]
Traceback (most recent call last):
  File "/Users/Supra/PycharmProjects/Flask_Tutorials/venv/lib/python2.7/site-packages/flask/app.py", line 2292, in wsgi_app
    response = self.full_dispatch_request()
  File "/Users/Supra/PycharmProjects/Flask_Tutorials/venv/lib/python2.7/site-packages/flask/app.py", line 1815, in full_dispatch_request
    rv = self.handle_user_exception(e)
  File "/Users/Supra/PycharmProjects/Flask_Tutorials/venv/lib/python2.7/site-packages/flask/app.py", line 1713, in handle_user_exception
    return self.handle_http_exception(e)
  File "/Users/Supra/PycharmProjects/Flask_Tutorials/venv/lib/python2.7/site-packages/flask/app.py", line 1644, in handle_http_exception
    return handler(e)
TypeError: not_found_error() takes no arguments (1 given)
2018-12-23 17:03:08,017 ERROR: Exception on /favicon.ico [GET] [in /Users/Supra/PycharmProjects/Flask_Tutorials/venv/lib/python2.7/site-packages/flask/app.py:1761]
Traceback (most recent call last):
  File "/Users/Supra/PycharmProjects/Flask_Tutorials/venv/lib/python2.7/site-packages/flask/app.py", line 2292, in wsgi_app
    response = self.full_dispatch_request()
  File "/Users/Supra/PycharmProjects/Flask_Tutorials/venv/lib/python2.7/site-packages/flask/app.py", line 1815, in full_dispatch_request
    rv = self.handle_user_exception(e)
  File "/Users/Supra/PycharmProjects/Flask_Tutorials/venv/lib/python2.7/site-packages/flask/app.py", line 1713, in handle_user_exception
    return self.handle_http_exception(e)
  File "/Users/Supra/PycharmProjects/Flask_Tutorials/venv/lib/python2.7/site-packages/flask/app.py", line 1644, in handle_http_exception
    return handler(e)
TypeError: not_found_error() takes no arguments (1 given)
2018-12-23 17:03:19,839 INFO: Microblog startup [in /Users/Supra/PycharmProjects/Flask_Tutorials/app/__init__.py:49]
2018-12-23 17:03:21,915 ERROR: Exception on /favicon.ico [GET] [in /Users/Supra/PycharmProjects/Flask_Tutorials/venv/lib/python2.7/site-packages/flask/app.py:1761]
Traceback (most recent call last):
  File "/Users/Supra/PycharmProjects/Flask_Tutorials/venv/lib/python2.7/site-packages/flask/app.py", line 2292, in wsgi_app
    response = self.full_dispatch_request()
  File "/Users/Supra/PycharmProjects/Flask_Tutorials/venv/lib/python2.7/site-packages/flask/app.py", line 1815, in full_dispatch_request
    rv = self.handle_user_exception(e)
  File "/Users/Supra/PycharmProjects/Flask_Tutorials/venv/lib/python2.7/site-packages/flask/app.py", line 1713, in handle_user_exception
    return self.handle_http_exception(e)
  File "/Users/Supra/PycharmProjects/Flask_Tutorials/venv/lib/python2.7/site-packages/flask/app.py", line 1644, in handle_http_exception
    return handler(e)
TypeError: not_found_error() takes no arguments (1 given)
